<?xml version="1.0" ?>
<robot xmlns:xacro="http://ros.org/wiki/xacro">
	<xacro:macro name="abby_gripper">
	<link name="gripper_body">
		<visual>
			<geometry>
				<mesh filename="package://abby_description/meshes/gripper_body.stl" scale="0.0254 0.0254 0.0254"/>
			</geometry>
			<origin rpy="0 0 0" xyz="0.987350237145 0.252969532498 0.91153488"/>
			<material name="gripper:21_color">
				<color rgba="0.752941 0.752941 0.752941 1"/>
			</material>
		</visual>
		<inertial>
			<mass value="0.222800943405"/>
			<inertia ixx="0.000113884956016" ixy="0.0" ixz="0.0" iyy="0.000132512764251" iyz="-4.2661207134e-07" izz="9.078477651e-05"/>
			<origin rpy="0 0 0" xyz="0.98735053139 0.252880388029 0.89481914"/>
		</inertial>
		<collision>
			<geometry>
				<mesh filename="package://abby_description/meshes/gripper_body.stl" scale="0.0254 0.0254 0.0254"/>
			</geometry>
			<origin rpy="0 0 0" xyz="0.987350237145 0.252969532498 0.91153488"/>
		</collision>
	</link>
	<link name="gripper_jaw_2">
		<visual>
			<geometry>
				<mesh filename="package://abby_description/meshes/gripper_jaw.stl" scale="0.0254 0.0254 0.0254"/>
			</geometry>
			<origin rpy="0 0 0" xyz="-0.00616234095847 -0.01853184 -0.0127004918295"/>
			<material name="gripper jaw:21_color">
				<color rgba="0.752941 0.752941 0.752941 1"/>
			</material>
		</visual>
		<inertial>
			<mass value="0.00921754126924"/>
			<inertia ixx="2.06132039615e-06" ixy="3.0409666492e-07" ixz="0.0" iyy="8.2195587923e-07" iyz="0.0" izz="1.7163745324e-06"/>
			<origin rpy="0 0 0" xyz="0 0 0"/>
		</inertial>
		<collision>
			<geometry>
				<mesh filename="package://abby_description/meshes/gripper_jaw.stl" scale="0.0254 0.0254 0.0254"/>
			</geometry>
			<origin rpy="0 0 0" xyz="-0.00616234095847 -0.01853184 -0.0127004918295"/>
		</collision>
	</link>
	<link name="gripper_jaw_1">
		<visual>
			<geometry>
				<mesh filename="package://abby_description/meshes/gripper_jaw.stl" scale="0.0254 0.0254 0.0254"/>
			</geometry>
			<origin rpy="0 0 0" xyz="-0.00634967993098 -0.015875 0"/>
			<material name="gripper jaw:11_color">
				<color rgba="0.752941 0.752941 0.752941 1"/>
			</material>
		</visual>
		<inertial>
			<mass value="0.00921754126924"/>
			<inertia ixx="2.06132039615e-06" ixy="3.0409666492e-07" ixz="0.0" iyy="8.2195587923e-07" iyz="0.0" izz="1.7163745324e-06"/>
			<origin rpy="0 0 0" xyz="-0.000187338972516 0.00265684 0.0127004023134"/>
		</inertial>
		<collision>
			<geometry>
				<mesh filename="package://abby_description/meshes/gripper_jaw.stl" scale="0.0254 0.0254 0.0254"/>
			</geometry>
			<origin rpy="0 0 0" xyz="-0.00634967993098 -0.015875 0"/>
		</collision>
	</link>
	<joint name="gripper_body--gripper_jaw_2" type="prismatic">
		<parent link="gripper_body"/>
		<child link="gripper_jaw_2"/>
		<origin rpy="-1.57079632679 0 3.14159265359" xyz="1.02008231217 0.253784397197 0.85691472"/>
	</joint>
	<joint name="gripper_jaw_2 -- gripper_jaw_1" type="prismatic">
		<parent link="gripper_jaw_2"/>
		<child link="gripper_jaw_1"/>
		<origin rpy="3.14159265359 0 -3.14159265359" xyz="0.0652760334972 -0.00265684 0.0126998117907"/>
	</joint>
  </xacro:macro>
</robot>
