<?xml version="1.0" ?>
<!-- =================================================================================== -->
<!-- |    This document was autogenerated by xacro from gripper.xacro                  | -->
<!-- |    EDITING THIS FILE BY HAND IS NOT RECOMMENDED                                 | -->
<!-- =================================================================================== -->
<robot name="abby_gripper" xmlns:xacro="http://ros.org/wiki/xacro">
  <link name="gripper_body">
    <visual>
      <geometry>
        <mesh filename="package://abby_description/meshes/gripper_body.stl" scale="0.0254 0.0254 0.0254"/>
      </geometry>
      <origin rpy="3.141592653 0 0" xyz="0 0 0.017"/>
      <material name="gripper:21_color">
        <color rgba="0.752941 0.752941 0.752941 1"/>
      </material>
    </visual>
    <inertial>
      <mass value="0.222800943405"/>
      <inertia ixx="0.000113884956016" ixy="0.0" ixz="0.0" iyy="0.000132512764251" iyz="-4.2661207134e-07" izz="9.078477651e-05"/>
      <origin rpy="3.141592653 0 0" xyz="0 0 0.013255"/>
    </inertial>
    <collision>
      <geometry>
        <box size="0.08 0.08 0.13"/>
        <!--cylinder radius="0.04" length="0.13" /-->
        <!--mesh filename="package://abby_description/meshes/gripper_body.stl" scale="0.0254 0.0254 0.0254"/-->
      </geometry>
      <origin rpy="0 0 0" xyz="0 0 0.065"/>
      <!--origin rpy="3.141592653 0 0" xyz="0 0 0.017"/-->
    </collision>
  </link>
  <link name="gripper_jaw_1">
    <visual>
      <geometry>
        <mesh filename="package://abby_description/meshes/gripper_jaw.stl" scale="0.0254 0.0254 0.0254"/>
      </geometry>
      <origin rpy="1.570796327 0 0" xyz="0 0.0127 0"/>
      <material name="gripper jaw:11_color">
        <color rgba="0.752941 0.752941 0.752941 1"/>
      </material>
    </visual>
    <inertial>
      <mass value="0.00921754126924"/>
      <inertia ixx="2.06132039615e-06" ixy="3.0409666492e-07" ixz="0.0" iyy="8.2195587923e-07" iyz="0.0" izz="1.7163745324e-06"/>
      <origin rpy="0 0 0" xyz="0.006162341 0.03123184 0.0127004023"/>
    </inertial>
    <collision>
      <geometry>
        <mesh filename="package://abby_description/meshes/gripper_jaw.stl" scale="0.0254 0.0254 0.0254"/>
      </geometry>
      <origin rpy="1.570796327 0 0" xyz="0 0.0127 0"/>
    </collision>
  </link>
  <link name="gripper_jaw_2">
    <visual>
      <geometry>
        <mesh filename="package://abby_description/meshes/gripper_jaw.stl" scale="0.0254 0.0254 0.0254"/>
      </geometry>
      <origin rpy="1.570796327 0 0" xyz="0 0.0127 0"/>
      <material name="gripper jaw:11_color">
        <color rgba="0.752941 0.752941 0.752941 1"/>
      </material>
    </visual>
    <inertial>
      <mass value="0.00921754126924"/>
      <inertia ixx="2.06132039615e-06" ixy="3.0409666492e-07" ixz="0.0" iyy="8.2195587923e-07" iyz="0.0" izz="1.7163745324e-06"/>
      <origin rpy="0 0 0" xyz="0.006162341 0.03123184 0.0127004023"/>
    </inertial>
    <collision>
      <geometry>
        <mesh filename="package://abby_description/meshes/gripper_jaw.stl" scale="0.0254 0.0254 0.0254"/>
      </geometry>
      <origin rpy="1.570796327 0 0" xyz="0 0.0127 0"/>
    </collision>
  </link>
  <joint name="gripper_jaw_1" type="prismatic">
    <parent link="gripper_body"/>
    <child link="gripper_jaw_1"/>
    <origin rpy="0 0 3.14159265359" xyz="0 0 0.062"/>
    <limit effort="1" lower="-0.039" upper="-0.03" velocity="1"/>
  </joint>
  <joint name="gripper_jaw_2" type="prismatic">
    <parent link="gripper_body"/>
    <child link="gripper_jaw_2"/>
    <origin rpy="0 0 0" xyz="0 0 0.062"/>
    <limit effort="1" lower="-0.039" upper="-0.03" velocity="1"/>
  </joint>
</robot>
